<?xml version="1.0"?>
<robot name="diff_drive_robot">

  <link name="base_link">
    <visual>
      <geometry><box size="0.4 0.2 0.1"/></geometry>
      <material name="blue"><color rgba="0 0 0.8 1"/></material>
    </visual>
    <collision><geometry><box size="0.4 0.2 0.1"/></geometry></collision>
    <inertial>
      <mass value="5"/>
      <inertia ixx="0.04" ixy="0" ixz="0" iyy="0.1" iyz="0" izz="0.1"/>
    </inertial>
  </link>

  <link name="right_wheel">
    <visual>
      <origin rpy="1.5707 0 0" xyz="0 0 0"/>
      <geometry><cylinder radius="0.05" length="0.04"/></geometry>
      <material name="black"><color rgba="0 0 0 1"/></material>
    </visual>
    <collision><origin rpy="1.5707 0 0" xyz="0 0 0"/><geometry><cylinder radius="0.05" length="0.04"/></geometry></collision>
    <inertial><mass value="1"/><inertia ixx="0.001" ixy="0" ixz="0" iyy="0.001" iyz="0" izz="0.002"/></inertial>
  </link>

  <joint name="right_wheel_joint" type="continuous">
    <parent link="base_link"/>
    <child link="right_wheel"/>
    <origin xyz="-0.1 -0.12 0" rpy="0 0 0"/>
    <axis xyz="0 1 0"/>
  </joint>

  <link name="left_wheel">
    <visual>
      <origin rpy="1.5707 0 0" xyz="0 0 0"/>
      <geometry><cylinder radius="0.05" length="0.04"/></geometry>
      <material name="black"><color rgba="0 0 0 1"/></material>
    </visual>
    <collision><origin rpy="1.5707 0 0" xyz="0 0 0"/><geometry><cylinder radius="0.05" length="0.04"/></geometry></collision>
    <inertial><mass value="1"/><inertia ixx="0.001" ixy="0" ixz="0" iyy="0.001" iyz="0" izz="0.002"/></inertial>
  </link>

  <joint name="left_wheel_joint" type="continuous">
    <parent link="base_link"/>
    <child link="left_wheel"/>
    <origin xyz="-0.1 0.12 0" rpy="0 0 0"/>
    <axis xyz="0 1 0"/>
  </joint>
  
  <gazebo>
    <plugin name="differential_drive_controller" filename="libgazebo_ros_diff_drive.so">
      <alwaysOn>true</alwaysOn>
      <updateRate>20</updateRate>
      <leftJoint>left_wheel_joint</leftJoint>
      <rightJoint>right_wheel_joint</rightJoint>
      <wheelSeparation>0.24</wheelSeparation>
      <wheelDiameter>0.1</wheelDiameter>
      <torque>10</torque>
      <commandTopic>cmd_vel</commandTopic>
      <odometryTopic>odom</odometryTopic>
      <odometryFrame>odom</odometryFrame>
      <robotBaseFrame>base_link</robotBaseFrame>
    </plugin>
  </gazebo>
</robot>
